Workbook

Sheet Arrendámientos
A1: Mes | B1: Kilos | C1: Promedio soja | D1: Total | E1: Nico | F1: Adelanto | G1: Total a cobrar | H1: Pagos | I1: Saldo anterior | J1: Resto en kilos | K1: Resto en $ | L1: Medio de pago
A2: Febrero (se paga en marzo) | C2: 489.505 | G2: 6123109 | J2: =G2/C2 -> 12508.777 | K2: =J2*C2 -> 6123109
A3: transferencia 09/03 | G3: =(B3*C3)-E3-F3 -> 0 | H3: 3000000 | I3: =K2 -> 6123109 | J3: =J2-((G2-H3)/C2) -> 6128.6402 | K3: =G3+I3-H3 -> 3123109
A4: Transferencia 11/03 | G4: =(B4*C4)-E4-F4 -> 0 | H4: 2000000 | I4: =K3 -> 3123109 | J4: =J3-((K3-H4)/C2) -> 3834.2632 | K4: =G4+I4-H4 -> 1123109 | L4: Cheque de 5mm
A5: Transferencia 20/03 | G5: =(B5*C5)-E5-F5 -> 0 | H5: 200000 | I5: =K4 -> 1123109 | J5: =J4-((K4-H5)/C2) -> 1948.4622 | K5: =G5+I5-H5 -> 923109
A6: Transferencia el 27/03 | G6: =(B6*C6)-E6-F6 -> 0 | H6: 923109 | I6: =K5 -> 923109 | J6: 0 | K6: =G6+I6-H6 -> 0

Sheet Flujo de caja
A1: FLUJO DE CAJA
A3: MES | B3: ENERO | C3: FEBRERO | D3: MARZO | E3: ABRIL | F3: MAYO | G3: JUNIO | H3: JULIO | I3: AGOSTO | J3: SEPTIEMBRE | K3: OCTUBRE | L3: NOVIEMBRE | M3: DICIEMBRE
A5: Sando inicial en caja
A7: Ingresos | B7: =SUM(B8:B15) -> 0 | C7: =SUM(C8:C15) -> 0 | D7: =SUM(D8:D15) -> 0 | E7: =SUM(E8:E15) -> 0 | F7: =SUM(F8:F15) -> 0 | G7: =SUM(G8:G15) -> 0 | H7: =SUM(H8:H15) -> 0 | I7: =SUM(I8:I15) -> 0 | ... M7: =SUM(M8:M15) -> 0
A8: Ventas granos
A9: Ventas hacienda
A10: Otras ventas
A11: Cheques
A12: Créditos
A13: Pymes
A14: Fletes
A15: Otros ingresos
A17: Egresos | B17: =SUM(B18:B26) -> 0 | C17: =SUM(C18:C26) -> 0 | D17: =SUM(D18:D26) -> 0 | E17: =SUM(E18:E26) -> 0 | F17: =SUM(F18:F26) -> 0 | G17: =SUM(G18:G26) -> 0 | H17: =SUM(H18:H26) -> 0 | I17: =SUM(I18:I26) -> 0 | ... M17: =SUM(M18:M26) -> 0
A18: Impuestos
A19: Servicios
A20: Empleados
A21: Proveedores
A22: Cuota créditos
A23: Extracción efectivo(bancos)
A24: Pago cheque
A25: Arrendamientos
A26: Otros
A28: Flujo de caja mensual | B28: =B7-B17 -> 0 | C28: =C7-C17 -> 0 | D28: =D7-D17 -> 0 | E28: =E7-E17 -> 0 | F28: =F7-F17 -> 0 | G28: =G7-G17 -> 0 | H28: =H7-H17 -> 0 | I28: =I7-I17 -> 0 | ... M28: =M7-M17 -> 0
A29: Flujo de caja acumulado | C29: =C28+B28 -> 0 | D29: =D28+C29 -> 0 | E29: =E28+D29 -> 0 | F29: =F28+E29 -> 0 | G29: =G28+F29 -> 0 | H29: =H28+G29 -> 0 | I29: =I28+H29 -> 0 | J29: =J28+I29 -> 0 | K29: =K28+J29 -> 0 | ... M29: =M28+L29 -> 0
A32: PERÍODO | B32: MONTO | C32: TIPO DE INGRESO | E32: PERÍODO | F32: MONTO | G32: TIPO DE EGRESO
A33: 02/26 | E33: 02/26 | F33: 8400000 | G33: CUOTA CREDITO
A34: 03/26 | B34: 1.1095718e+08 | C34: CREDITO | E34: 02/26 | F34: 115000 | G34: CUOTA CREDITO
A35: 03/26 | E35: 02/26 | F35: 36520.5 | G35: OTROS
E36: 02/26 | F36: 125905.73 | G36: PROVEEDORES
E37: 02/26 | F37: 21000 | G37: PROVEEDORES
E38: 02/26 | F38: 33000 | G38: PROVEEDORES
E39: 02/26 | F39: 857500 | G39: EMPLEADOS
E40: 02/26 | F40: 840000 | G40: EMPLEADOS
E41: 02/26 | F41: 795000 | G41: EMPLEADOS
E42: 02/26 | F42: =728000+156000 -> 884000 | G42: EMPLEADOS
E43: 02/26 | F43: 423000 | G43: EMPLEADOS
A51: PERIODO | B51: GRANOS | C51: HACIENDA | D51: FLETES | E51: PYME | F51: CREDITO | G51: CHEQUES | H51: OTRAS VENTAS | I51: OTROS INGRESOS | L51: PERIODO | M51: IMPUESTOS | N51: SERVICIOS | O51: EMPLEADOS | P51: PROVEEDORES | Q51: CUOTA CREDITO | R51: RETIROS EFECTIVO | S51: ARRENDAMIENTOS | T51: OTROS | U51: PAGO CHEQUE
A52: 01/26 | B52: =SUMIFS(INGRESOS!B:B,INGRESOS!A:A,"01/26",INGRESOS!C:C,"GRANOS") -> #N/A | C52: =SUMIFS(INGRESOS!B:B,INGRESOS!A:A,"01/26",INGRESOS!C:C,"HACIENDA") -> #N/A | D52: =SUMIFS(INGRESOS!B:B,INGRESOS!A:A,"01/26",INGRESOS!C:C,"FLETES") -> #N/A | E52: =SUMIFS(INGRESOS!B:B,INGRESOS!A:A,"01/26",INGRESOS!C:C,"PYME") -> #N/A | F52: =SUMIFS(INGRESOS!B:B,INGRESOS!A:A,"01/26",INGRESOS!C:C,"CREDITO") -> #N/A | G52: =SUMIFS(INGRESOS!B:B,INGRESOS!A:A,"01/26",INGRESOS!C:C,"CHEQUES") -> #N/A | H52: =SUMIFS(INGRESOS!B:B,INGRESOS!A:A,"01/26",INGRESOS!C:C,"OTRAS VENTAS") -> #N/A | I52: =SUMIFS(INGRESOS!B:B,INGRESOS!A:A,"01/26",INGRESOS!C:C,"OTROS INGRESOS") -> #N/A | L52: 01/26 | M52: =SUMIFS(EGRESOS!B:B,EGRESOS!A:A,"01/26",EGRESOS!C:C,"IMPUESTOS") -> #N/A | N52: =SUMIFS(EGRESOS!B:B,EGRESOS!A:A,"01/26",EGRESOS!C:C,"SERVICIOS") -> #N/A | O52: =SUMIFS(EGRESOS!B:B,EGRESOS!A:A,"01/26",EGRESOS!C:C,"EMPLEADOS") -> #N/A | P52: =SUMIFS(EGRESOS!B:B,EGRESOS!A:A,"01/26",EGRESOS!C:C,"PROVEEDORES") -> #N/A | Q52: =SUMIFS(EGRESOS!B:B,EGRESOS!A:A,"01/26",EGRESOS!C:C,"CUOTA CREDITO") -> #N/A | R52: =SUMIFS(EGRESOS!B:B,EGRESOS!A:A,"01/26",EGRESOS!C:C,"RETIROS EFECTIVO") -> #N/A | S52: =SUMIFS(EGRESOS!B:B,EGRESOS!A:A,"01/26",EGRESOS!C:C,"ARRENDAMIENTOS") -> #N/A | T52: =SUMIFS(EGRESOS!B:B,EGRESOS!A:A,"01/26",EGRESOS!C:C,"OTROS") -> #N/A | U52: =SUMIFS(EGRESOS!B:B,EGRESOS!A:A,"01/26",EGRESOS!C:C,"PAGO CHEQUE") -> #N/A
A53: 02/26 | B53: =SUMIFS(INGRESOS!B:B,INGRESOS!A:A,"02/26",INGRESOS!C:C,"GRANOS") -> #N/A | C53: =SUMIFS(INGRESOS!B:B,INGRESOS!A:A,"02/26",INGRESOS!C:C,"HACIENDA") -> #N/A | D53: =SUMIFS(INGRESOS!B:B,INGRESOS!A:A,"02/26",INGRESOS!C:C,"FLETES") -> #N/A | E53: =SUMIFS(INGRESOS!B:B,INGRESOS!A:A,"02/26",INGRESOS!C:C,"PYME") -> #N/A | F53: =SUMIFS(INGRESOS!B:B,INGRESOS!A:A,"02/26",INGRESOS!C:C,"CREDITO") -> #N/A | G53: =SUMIFS(INGRESOS!B:B,INGRESOS!A:A,"02/26",INGRESOS!C:C,"CHEQUES") -> #N/A | H53: =SUMIFS(INGRESOS!B:B,INGRESOS!A:A,"02/26",INGRESOS!C:C,"OTRAS VENTAS") -> #N/A | I53: =SUMIFS(INGRESOS!B:B,INGRESOS!A:A,"02/26",INGRESOS!C:C,"OTROS INGRESOS") -> #N/A | L53: 02/26 | M53: =SUMIFS(EGRESOS!B:B,EGRESOS!A:A,"02/26",EGRESOS!C:C,"IMPUESTOS") -> #N/A | N53: =SUMIFS(EGRESOS!B:B,EGRESOS!A:A,"02/26",EGRESOS!C:C,"SERVICIOS") -> #N/A | O53: =SUMIFS(EGRESOS!B:B,EGRESOS!A:A,"02/26",EGRESOS!C:C,"EMPLEADOS") -> #N/A | P53: =SUMIFS(EGRESOS!B:B,EGRESOS!A:A,"02/26",EGRESOS!C:C,"PROVEEDORES") -> #N/A | Q53: =SUMIFS(EGRESOS!B:B,EGRESOS!A:A,"02/26",EGRESOS!C:C,"CUOTA CREDITO") -> #N/A | R53: =SUMIFS(EGRESOS!B:B,EGRESOS!A:A,"02/26",EGRESOS!C:C,"RETIROS EFECTIVO") -> #N/A | S53: =SUMIFS(EGRESOS!B:B,EGRESOS!A:A,"02/26",EGRESOS!C:C,"ARRENDAMIENTOS") -> #N/A | T53: =SUMIFS(EGRESOS!B:B,EGRESOS!A:A,"02/26",EGRESOS!C:C,"OTROS") -> #N/A | U53: =SUMIFS(EGRESOS!B:B,EGRESOS!A:A,"02/26",EGRESOS!C:C,"PAGO CHEQUE") -> #N/A
A54: 03/26 | B54: =SUMIFS(INGRESOS!B:B,INGRESOS!A:A,"03/26",INGRESOS!C:C,"GRANOS") -> #N/A | C54: =SUMIFS(INGRESOS!B:B,INGRESOS!A:A,"03/26",INGRESOS!C:C,"HACIENDA") -> #N/A | D54: =SUMIFS(INGRESOS!B:B,INGRESOS!A:A,"03/26",INGRESOS!C:C,"FLETES") -> #N/A | E54: =SUMIFS(INGRESOS!B:B,INGRESOS!A:A,"03/26",INGRESOS!C:C,"PYME") -> #N/A | F54: =SUMIFS(INGRESOS!B:B,INGRESOS!A:A,"03/26",INGRESOS!C:C,"CREDITO") -> #N/A | G54: =SUMIFS(INGRESOS!B:B,INGRESOS!A:A,"03/26",INGRESOS!C:C,"CHEQUES") -> #N/A | H54: =SUMIFS(INGRESOS!B:B,INGRESOS!A:A,"03/26",INGRESOS!C:C,"OTRAS VENTAS") -> #N/A | I54: =SUMIFS(INGRESOS!B:B,INGRESOS!A:A,"03/26",INGRESOS!C:C,"OTROS INGRESOS") -> #N/A | L54: 03/26 | M54: =SUMIFS(EGRESOS!B:B,EGRESOS!A:A,"03/26",EGRESOS!C:C,"IMPUESTOS") -> #N/A | N54: =SUMIFS(EGRESOS!B:B,EGRESOS!A:A,"03/26",EGRESOS!C:C,"SERVICIOS") -> #N/A | O54: =SUMIFS(EGRESOS!B:B,EGRESOS!A:A,"03/26",EGRESOS!C:C,"EMPLEADOS") -> #N/A | P54: =SUMIFS(EGRESOS!B:B,EGRESOS!A:A,"03/26",EGRESOS!C:C,"PROVEEDORES") -> #N/A | Q54: =SUMIFS(EGRESOS!B:B,EGRESOS!A:A,"03/26",EGRESOS!C:C,"CUOTA CREDITO") -> #N/A | R54: =SUMIFS(EGRESOS!B:B,EGRESOS!A:A,"03/26",EGRESOS!C:C,"RETIROS EFECTIVO") -> #N/A | S54: =SUMIFS(EGRESOS!B:B,EGRESOS!A:A,"03/26",EGRESOS!C:C,"ARRENDAMIENTOS") -> #N/A | T54: =SUMIFS(EGRESOS!B:B,EGRESOS!A:A,"03/26",EGRESOS!C:C,"OTROS") -> #N/A | U54: =SUMIFS(EGRESOS!B:B,EGRESOS!A:A,"03/26",EGRESOS!C:C,"PAGO CHEQUE") -> #N/A
...

Sheet Control stock granos
A1: KG CARGA | B1: FECHA DE LA CARGA | C1: CPE
E2: HA | F2: QQ | G2: KG ESTIMATIVOS
E3: 30 | F3: 90 | G3: =(E3*F3)*100 -> 270000
E5: TOTAL INICIAL | F5: 270000
E6: TOTAL DE CARGAS | F6: =SUM(A2:A25) -> 0
E7: TOTAL DISPONIBLE | F7: =F5-F6 -> 270000

Sheet Control stock hacienda
A1: RENSPA: 03.014.1.03312/00
A3: Especie | B3: Categoria | C3: Stock | D3: Cambio | E3: Stock real | F3: Diferencia | G3: Notas
A4: Bovino | B4: Vaca | C4: 19 | E4: 19 | F4: =E4-C4 -> 0
A5: Bovino | B5: Ternero | C5: 19 | E5: 19 | F5: =E5-C5 -> 0

Sheet Venta granos
A1: Fecha | B1: Carga de camión | C1: Kilos de descargas | D1: Kilos de descuento | E1: Kilos totales | F1: Pizarra al día | G1: Descuento | H1: Descuento de pizarra | I1: Importe | J1: Importe total | K1: Carga flete | L1: Ultimo saldo | M1: Total | N1: Entrega | O1: Medio de pago | P1: Saldo final
A2: 45478 | B2: Maiz | C2: 34580 | E2: =C2-D2 -> 34580 | F2: 156.2 | H2: 12 | I2: =F2-H2 -> 144.2 | J2: =I2*E2 -> 4986436 | M2: =J2+L2+K2 -> 4986436 | P2: =M2-N2 -> 4986436
A3: 45482 | B3: Maiz | C3: 25400 | E3: =C3-D3 -> 25400 | F3: 150 | H3: 12 | I3: =F3-H3 -> 138 | J3: =I3*E3 -> 3505200 | L3: =P2 -> 4986436 | M3: =J3+L3+K3 -> 8491636 | P3: =M3-N3 -> 8491636
A4: 45484 | B4: Maiz | C4: 24960 | E4: =C4-D4 -> 24960 | F4: 154.85 | H4: 12 | I4: =F4-H4 -> 142.85 | J4: =I4*E4 -> 3565536 | L4: =P3 -> 8491636 | M4: =J4+L4+K4 -> 12057172 | P4: =M4-N4 -> 12057172

Sheet Venta hacienda
A1: Fecha | B1: Carga de camión | C1: Kilos Bruto | D1: Kilos Tara | E1: Kilos Neto | F1: Desvaste | G1: Descuento de pizarra | H1: Kilos totales | I1: Precio | J1: Importe total | K1: IVA | L1: Ultimo saldo | M1: Total | N1: Entrega | O1: Medio de pago | P1: Saldo final
A2: 46061 | B2: Bovinos | C2: 22460 | D2: 14960 | E2: =C2-D2 -> 7500 | F2: 0.08 | G2: =E2*F2 -> 600 | H2: =E2-G2 -> 6900 | I2: 4900 | J2: =H2*I2 -> 33810000 | M2: =J2+L2+K2 -> 33810000 | N2: 25616250 | O2: 2 echeq | P2: =M2-N2 -> 8193750
A3: 46062 | E3: =C3-D3 -> 0 | G3: =E3*F3 -> 0 | H3: =I3-G3 -> 0 | J3: =H3*I3 -> 0 | L3: =P2 -> 8193750 | M3: =J3+L3+K3 -> 8193750 | N3: 3000000 | O3: transfiere a llsp bna | P3: =M3-N3 -> 5193750
A4: 46064 | E4: =C4-D4 -> 0 | G4: =E4*F4 -> 0 | H4: =I4-G4 -> 0 | J4: =H4*I4 -> 0 | L4: =P3 -> 5193750 | M4: =J4+L4+K4 -> 5193750 | N4: 3188670 | O4: transfiere a llsp bna | P4: =M4-N4 -> 2005080

Sheet Campañas
A1: CAMPO LOTE 1 CONTRA MINCOF | C1: 22 | D1: HA | H1: Aplicacion/labor | I1: U$S
A2: SIEMBRA | B2: Centeno | H2: Siembra | I2: 40
A3: TC | H3: Semilla | I3: 20
A4: U$S/ TON | C4: A COBRAR | H4: Pulverizada | I4: 5
A7: Cultivo | B7: Centeno
A8: Insumos y labores | B8: Unidades/ha | C8: u$s/unidad | D8: u$s/ha | E8: u$s/ha IVA inc | F8: Total u$s (sin IVA) | G8: Total líquidos | H8: Observaciones | I8: Fecha
A9: Glifosato | B9: 2 | D9: =B9*C9 -> 0 | F9: =D9*C1 -> 0 | G9: =B9*C1 -> 44 | I9: 45802
A10: 2-4 D | B10: 0.5 | C10: 5.8 | D10: =B10*C10 -> 2.9 | F10: =D10*C1 -> 63.8 | G10: =B10*C1 -> 11 | I10: 45802
A11: Strimg | B11: 0.12 | D11: =B11*C11 -> 0 | F11: =D11*C1 -> 0 | G11: =B11*C1 -> 2.64 | I11: 45802
A12: Bambel | B12: 0.2 | D12: =B12*C12 -> 0 | F12: =D12*C1 -> 0 | G12: =B12*C1 -> 4.4 | I12: 45802
A13: Glufosinato | B13: 2 | D13: =B13*C13 -> 0 | F13: =D13*C1 -> 0 | G13: =B13*C1 -> 44 | I13: 46019
A14: 24D enlis | B14: 2 | D14: =B14*C14 -> 0 | F14: =D14*C1 -> 0 | G14: =B14*C1 -> 44
A15: Glifosato | B15: 2 | D15: =B15*C15 -> 0 | F15: =D15*C1 -> 0 | G15: =B15*C1 -> 44
A16: Eco rizo | B16: 0.07 | D16: =B16*C16 -> 0 | F16: =D16*C1 -> 0 | G16: =B16*C1 -> 1.54
A17: Insecticida | D17: =B17*C17 -> 0 | F17: =D17*C1 -> 0 | G17: =B17*C1 -> 0
A18: Pulverizada | B18: 1 | C18: 5 | D18: =B18*C18 -> 5 | F18: =D18*C1 -> 110 | I18: 46019
A19: Glifo | B19: =50/22 -> 2.2727273 | D19: =B19*C19 -> 0 | F19: =D19*C1 -> 0 | G19: =B19*C1 -> 50 | I19: 46031
A20: Atrazina | B20: =30/22 -> 1.3636364 | D20: =B20*C20 -> 0 | F20: =D20*C1 -> 0 | G20: =B20*C1 -> 30
A21: Voraxor | B21: =3/22 -> 0.13636364 | D21: =B21*C21 -> 0 | F21: =D21*C1 -> 0 | G21: =B21*C1 -> 3
A22: 24D | B22: =20/22 -> 0.90909091 | D22: =B22*C22 -> 0 | F22: =D22*C1 -> 0 | G22: =B22*C1 -> 20

Sheet Control de cheques
A1: Banco Emisor | B1: Numero de cheque | C1: Tipo de cheque | D1: Titular | E1: CUIT Titular | F1: Fecha de recepcion | G1: Fecha de entrega | H1: Fecha de pago | I1: Monto | J1: Origen | K1: Destino | L1: Estado | M1: Quien lo recibe
A2: Banco San Juan | B2: 123 | C2: Fisico | D2: Valli Enrique Federico | E2: 11-11111111-1 | F2: 45736 | I2: 555
A3: BBVA Frances | B3: 123 | C3: Fisico | D3: Perotti German Antonio | E3: 11-11111111-1 | F3: 45736 | I3: 555555
A4: Banco Coinag | B4: 123 | C4: Fisico | D4: Hudson Servicios | E4: 11-11111111-1 | F4: 46101 | H4: 46133 | I4: 55555 | J4: Nuxen | K4: depositado en el macro | M4: Oficina
A5: Banco industrial | B5: 123 | C5: Fisico | D5: lartirigoyen y cia s.a | E5: 11-11111111-1 | F5: 46118 | H5: 46137 | I5: 55555 | J5: De next agro | M5: Oficina
A6: Banco Coinag | B6: 123 | C6: Fisico | D6: Hudson Servicios | E6: 11-11111111-1 | F6: 46101 | H6: 46140 | I6: 55555 | J6: nuxen | M6: Oficina

Sheet Gastossueldos
A1: Monto | B1: Descripcion | C1: Fecha de inicio
A2: 1000000 | B2: Transfiere a Ingrid | C2: 45902
A3: 1000000 | B3: Transfiere a cuenta Luciano | C3: 45903
A4: 60000 | B4: german alvarado | C4: 45903
A5: 20000 | B5: julio santillan | C5: 45905
A6: 12516.26 | B6: Arca luciano | C6: 45907
A9: SUELDOS EMPLEADOS:
A10: Fecha de inicio: 01/04/26
A12: Dias trabajados | B12: Dias NO trabajados | C12: Cobra p/dia | D12: TOTAL A COBRAR | F12: TOTAL | G12: =D13+I17 -> 320000
A13: 10 | B13: 1 | C13: 30000 | D13: =(A13-B13)*C13 -> 270000 | F13: GASTOS/TRANSFERENCIAS | G13: =SUM(Gastos_empleados[Monto]) -> 3700
F14: TOTAL A COBRAR | G14: =G12-G13 -> 316300
A16: Monto | B16: Descripcion | C16: Estado | D16: Fecha de inicio | E16: Fecha de finalización | F16: Notas | H16: MES | I16: MONTO
A17: 1200 | B17: 4 jugos | C17: Pendiente | D17: 46115 | H17: Marzo | I17: 50000
A18: 2500 | B18: atado | C18: Pendiente | D18: 46128
A23: Fecha | B23: Concepto | C23: Monto | D23: Adelanto | E23: Detalle
B24: Mutual | C24: 132013.57
B25: Monotributo | C25: 60336.74 | G25: SUELDO BASE | H25: 1200000
A26: 46093 | B26: Otro | C26: 2000 | E26: seguro empleados | G26: EXTRA | H26: =SUM(Vicki!$C$2:$C$15) -> #REF!
G27: ADELANTO | H27: =SUM(Vicki!$D$2:$D$15) -> #REF!
G28: TOTAL | H28: =H25+H26-H27 -> #REF!

Sheet PyME
A1: Fecha grupo | B1: Tipo | C1: KG | D1: Estado | E1: Precio por KG | F1: Total | G1: Entregado a | H1: Notas
A2: 46082 | B2: Lechon | C2: 18 | D2: No pago | E2: 11500 | F2: =C2*E2 -> 207000 | G2: Para Denise y Valen BNA
A3: 46082 | B3: Lechon | C3: 14 | D3: No pago | E3: 10000 | F3: =C3*E3 -> 140000 | G3: Vendió Luciano
A4: 46082 | B4: Lechon | C4: 11 | D4: No pago | E4: 10000 | F4: =C4*E4 -> 110000 | G4: Retiró Gerardo
A5: 46082 | B5: Cordero | C5: 10 | D5: No pago | E5: 11500 | F5: =C5*E5 -> 115000 | G5: Matin dos banderas
A6: 46090 | B6: Chivito | C6: 9 | D6: Pago | E6: 11500 | F6: =C6*E6 -> 103500
A7: 46090 | B7: Lechon | C7: 14 | D7: Pago | E7: 10000 | F7: =C7*E7 -> 140000

Sheet Cuentas corrientes
A1: Nombre del cliente / proveedor | B1: Saldo total | C1: Transferencia o echeq | D1: Fecha de la solicitud | E1: Prioridad | F1: Estado de la cuenta | G1: Observaciones
A2: Mascanfroni Angel | B2: 240000 | C2: Echeq | D2: 45943 | E2: Baja | F2: Pendiente | G2: BABEL.DEBATE.RENO
A3: Rentas LLSP | B3: 809854.43 | C3: Transferencia | E3: Media | F3: Pendiente | G3: Meses adeudados: sep y oct
A4: Rentas El Pistrin | B4: 195105.46 | C4: Efectivo | E4: Alta | F4: Pendiente | G4: Meses adeudados: sep y oct

Sheet Control efectivo
A1: Fecha | B1: Ingreso | C1: Recibido por | D1: Cuenta de | E1: Egreso | F1: Entregado a | G1: Disponible
A2: 46086 | B2: 600000 | C2: Administración | G2: =B2-E2 -> 600000
A3: 46087 | E3: 290000 | F3: Luciano (250 Claudio, 40 Osmar) | G3: =B3+G2-E3 -> 310000
A4: 46087 | B4: 700 | C4: Administración | D4: Sobró de pagos de servicios. de Gerardo | G4: =B4+G3-E4 -> 310700
A5: 46090 | E5: 300000 | F5: Facha | G5: =B5+G4-E5 -> 10700
A6: 46091 | B6: 132000 | C6: Administración | D6: De melchor (negocio de avena y centeno) | G6: =B6+G5-E6 -> 142700
A7: 46091 | E7: 6600 | F7: Yerba oficina | G7: =B7+G6-E7 -> 136100
A10: Fecha | B10: Ingreso | C10: Recibido por | D10: Egreso | E10: Entregado a | F10: Disponible
A11: 46086 | B11: 600000 | C11: Administración | F11: =B11-D11 -> 600000
A12: 46087 | D12: 290000 | E12: Luciano (250 Claudio, 40 Osmar) | F12: =B12+F11-D12 -> 310000
A13: 46087 | B13: 700 | C13: Administración | F13: =B13+F12-D13 -> 310700
A14: 46090 | D14: 300000 | E14: Facha | F14: =B14+F13-D14 -> 10700
A15: 46091 | B15: 132000 | C15: Administración | F15: =B15+F14-D15 -> 142700
A18: Fecha de inicio | B18: Activos | C18: Tipo de pasivo | D18: Pasivos empresa | E18: Pasivos Familia | F18: Descripcion | G18: Columna 1
A19: 46086 | B19: 160000
A20: 46093 | B20: 700000 | F20: Retiró Ingrid de oficina | H20: TOTAL ACTIVOS | J20: TOTAL PASIVOS EMPRESA | L20: TOTAL PASIVOS FLIA | N20: A FAVOR
A21: 46093 | C21: PROPIO | E21: 700000 | F21: Gas casa sobremonte | H21: =SUM(B18:B321) -> 1460555 | J21: =SUM(D18:D321) -> 22666 | L21: =SUM(E18:E321) -> 1300000 | N21: =H21-J21-L21 -> 137889
A22: 46093 | B22: 600000 | F22: Retira luciano de la oficina | N22: =H22-J22-L22 -> 0
A23: 46093 | C23: PROPIO | E23: 600000 | F23: Torino
A24: 46101 | B24: 555
A25: 46112 | C25: EMPRESA | D25: 22666 | F25: Deja en la oficina

Sheet Hojas de viajes camioneros
A1: Fecha de INICIO | B1: Lugar de partida - Destino | C1: Transporta | D1: CTG | E1: Num de CDP | F1: KM de inicio | G1: MC DE GAS | H1: Gastos de gas/combustible | I1: Gastos de peajes | J1: Gastos de comida | K1: Gastos varios | L1: Fecha de finalizacion | M1: KM al finalizar | N1: KM recorridos | O1: KG de descarga | P1: Gastos totales | Q1: Transferencias | R1: Efectivo | S1: Sobrante viaje anterior | T1: Resto de dinero | U1: Observaciones
A2: 45879 | B2: Acequias - santa fe | C2: maiz | D2: 10125855087 | E2: 390 | F2: 73509 | G2: 304625 | I2: 10200 | J2: 24000 | K2: 13500 | L2: 45880 | N2: =M2-F2 -> -73509 | O2: 27980 | P2: =SUM(H2:K2) -> 47700 | Q2: 100000 | R2: 30000 | S2: =#REF! -> #REF! | T2: 500
A3: 45881 | B3: acequias - santa fe | C3: maiz | D3: 10125888890 | E3: 394 | G3: 348673 | I3: 10200 | J3: 37000 | K3: 13500 | L3: 45882 | M3: 75470 | N3: =M3-F3 -> 75470 | O3: 27830 | P3: =SUM(H3:K3) -> 60700 | Q3: 200000 | S3: =T2 -> 500 | T3: 18200
A4: 45896 | B4: Chucul - Santa Fe | C4: Soja | D4: 10126162946 | E4: 199 | F4: 77890 | G4: 354987 | I4: 10200 | J4: 23000 | K4: 36400 | L4: 45898 | M4: 78711 | N4: =M4-F4 -> 821 | O4: 27880 | P4: =SUM(H4:K4) -> 69600 | Q4: 34000 | R4: 50000 | S4: =T3 -> 18200 | T4: 16800 | U4: Chala mani de laguna al campo
A5: 45898 | B5: Holberg - Gral Deheza | C5: Girasol | D5: 10126331532 | E5: 398 | F5: 78910 | G5: 259 | H5: 171264 | I5: 31200 | J5: 0 | K5: 0 | L5: 45903 | M5: 79218 | N5: =M5-F5 -> 308 | O5: 12790 | P5: =I5+K5 -> 31200 | Q5: 31200 | R5: 0 | S5: 0 | T5: =R5+Q5+S5-P5 -> 0 | U5: Se trajo 35460k de piedra desde los condores al campo
A6: 45916 | B6: La carolina - Timbues renova | C6: Soja | D6: 10126518083 | E6: 3 | F6: 79484 | G6: 497 | H6: 392672 | I6: 20400 | J6: 10000 | K6: 70900 | L6: 45918 | M6: 80484 | N6: =M6-F6 -> 1000 | P6: =I6+K6 -> 91300 | Q6: 100000 | S6: =T5 -> 0 | T6: =R6+Q6+S6-P6 -> 8700 | U6: El conto la comida y los numeros no dan.
A7: 45920 | B7: La carolina - cofco | C7: Soja | D7: 10126575387 | E7: 5 | F7: 80484 | G7: 289 | H7: 232165 | I7: 10200 | J7: 10000 | K7: 17900 | L7: 45921 | M7: 81515 | N7: =M7-F7 -> 1031 | O7: 27900 | P7: =I7+K7+J7 -> 38100 | Q7: 50000 | S7: =T6 -> 8700 | T7: =R7+Q7+S7-P7 -> 20600 | U7: Conto la comida
